Workbook

Sheet README_DataQuality
A1: Item | B1: Value
A2: Historical period requested | B2: 2025-09-02 → 2026-09-24
A3: Period for which V15 verdicts are RECORDED in the package | B3: 2025-09-30 → 2026-09-03 (first catch 2025-10-01, last catch 2026-09-03)
A4: Number of recovered sessions (with recorded V15 verdicts) | B4: 229 sessions
A5: Sessions in requested period with raw data but NO usable V15 verdict | B5: 34 sessions (see Missing_History) — warm-up 20, zero-filled delivery 7, no recorded run 7
A6: Number of confirmed catch events (engine event grouping) | B6: 769 events
A7: Number of confirmed catch-DAYS (one row per symbol per confirmed session) | B7: 852 (697 single-day events + 61 two-day + 11 three-day streaks = 852)
A8: Number of unique confirmed symbols | B8: 192
A9: Catch-days with verified current prices | B9: 848
A10: Catch-days WITHOUT current prices | B10: 4 (symbol LTIM has no row on the latest session)
A11: Previously reported audit total | B11: 913 confirmed events / 193 unique symbols
A12: Recovered event total | B12: 852 catch-days (769 grouped events)
... A21: Safety check | B21: NO CODE CHANGED · NO V15 RULE CHANGED · NO DATA MODIFIED · NO REPLAY PERFORMED · NO NEW REPOSITORY CREATED · NO PUSH/COMMIT/PR/MERGE PERFORMED · NO FUTURE DATA USED TO DETERMINE HISTORICAL V15 CONFIRMATIONS · NO MISSING DATA TREATED AS ZERO · NO PRICES INVENTED · NO CATCH EVENTS INVENTED

Sheet T1_Catches
A1: Catch Date | B1: Symbol | C1: Company Name | D1: Catch Price | E1: V15 / Accumulation Score | F1: Delivery % | G1: Volume Ratio | H1: OBV | I1: OI | J1: OI Change | K1: Confirmation Gate Status | L1: Evidence / Source | M1: Scanner Evidence ID / Git Commit | N1: Event Index | O1: Streak Day | P1: Event Status
A2: 2025-10-01 | B2: APLAPOLLO | C2: APL Apollo Tubes Limited | D2: 1731.1 | E2: N/A | F2: 65.29 | G2: N/A | H2: N/A | I2: 9691150 | J2: 306950 | K2: ACCUMULATION CONFIRMED (engine verdict; per-gate values not stored) | L2: RECORDED: backtest/REAL_1YEAR_BACKTEST_RESULT.json signals[] | M2: BT:APLAPOLLO#e0d1of1 (git commit N/A) | N2: 0 | O2: 1/1 | P2: New
A3: 2025-10-01 | B3: DIVISLAB | C3: Divi's Laboratories Limited | D3: 5710 | E3: N/A | F3: 75.65 | G3: N/A | H3: N/A | I3: 2668500 | J3: 96900 | K3: ACCUMULATION CONFIRMED (engine verdict; per-gate values not stored) | L3: RECORDED: backtest/REAL_1YEAR_BACKTEST_RESULT.json signals[] | M3: BT:DIVISLAB#e0d1of2 (git commit N/A) | N3: 0 | O3: 1/2 | P3: Active
A4: 2025-10-01 | B4: FORTIS | C4: Fortis Healthcare Limited | D4: 989.65 | E4: N/A | F4: 55.55 | G4: N/A | H4: N/A | I4: 7263300 | J4: 99975 | K4: ACCUMULATION CONFIRMED (engine verdict; per-gate values not stored) | L4: RECORDED: backtest/REAL_1YEAR_BACKTEST_RESULT.json signals[] | M4: BT:FORTIS#e0d1of1 (git commit N/A) | N4: 0 | O4: 1/1 | P4: New
A5: 2025-10-01 | B5: ICICIGI | C5: ICICI Lombard General Insurance Company Limited | D5: 1903.6 | E5: N/A | F5: 70.09 | G5: N/A | H5: N/A | I5: 5046275 | J5: 77025 | K5: ACCUMULATION CONFIRMED (engine verdict; per-gate values not stored) | L5: RECORDED: backtest/REAL_1YEAR_BACKTEST_RESULT.json signals[] | M5: BT:ICICIGI#e0d1of1 (git commit N/A) | N5: 0 | O5: 1/1 | P5: New
A6: 2025-10-01 | B6: IEX | C6: Indian Energy Exchange Limited | D6: 141.18 | E6: N/A | F6: 61.21 | G6: N/A | H6: N/A | I6: 48900000 | J6: 4117500 | K6: ACCUMULATION CONFIRMED (engine verdict; per-gate values not stored) | L6: RECORDED: backtest/REAL_1YEAR_BACKTEST_RESULT.json signals[] | M6: BT:IEX#e0d1of2 (git commit N/A) | N6: 0 | O6: 1/2 | P6: Active
A7: 2025-10-01 | B7: MFSL | C7: Max Financial Services Limited | D7: 1621.9 | E7: N/A | F7: 59.75 | G7: N/A | H7: N/A | I7: 5804800 | J7: 133600 | K7: ACCUMULATION CONFIRMED (engine verdict; per-gate values not stored) | L7: RECORDED: backtest/REAL_1YEAR_BACKTEST_RESULT.json signals[] | M7: BT:MFSL#e0d1of1 (git commit N/A) | N7: 0 | O7: 1/1 | P7: New
A8: 2025-10-01 | B8: SRF | C8: SRF Limited | D8: 2907.1 | E8: N/A | F8: 51.45 | G8: N/A | H8: N/A | I8: 2878600 | J8: 75800 | K8: ACCUMULATION CONFIRMED (engine verdict; per-gate values not stored) | L8: RECORDED: backtest/REAL_1YEAR_BACKTEST_RESULT.json signals[] | M8: BT:SRF#e0d1of1 (git commit N/A) | N8: 0 | O8: 1/1 | P8: New
A9: 2025-10-01 | B9: YESBANK | C9: Yes Bank Limited | D9: 21.76 | E9: N/A | F9: 51.51 | G9: N/A | H9: N/A | I9: 804463700 | J9: 32188500 | K9: ACCUMULATION CONFIRMED (engine verdict; per-gate values not stored) | L9: RECORDED: backtest/REAL_1YEAR_BACKTEST_RESULT.json signals[] | M9: BT:YESBANK#e0d1of1 (git commit N/A) | N9: 0 | O9: 1/1 | P9: New
A10: 2025-10-03 | B10: BAJAJ-AUTO | C10: Bajaj Auto Limited | D10: 8679.5 | E10: N/A | F10: 61.94 | G10: N/A | H10: N/A | I10: 3215850 | J10: 59100 | K10: ACCUMULATION CONFIRMED (engine verdict; per-gate values not stored) | L10: RECORDED: backtest/REAL_1YEAR_BACKTEST_RESULT.json signals[] | M10: BT:BAJAJ-AUTO#e0d1of1 (git commit N/A) | N10: 0 | O10: 1/1 | P10: New
A11: 2025-10-03 | B11: DALBHARAT | C11: Dalmia Bharat Limited | D11: 2253.7 | E11: N/A | F11: 66.81 | G11: N/A | H11: N/A | I11: 2353325 | J11: 133250 | K11: ACCUMULATION CONFIRMED (engine verdict; per-gate values not stored) | L11: RECORDED: backtest/REAL_1YEAR_BACKTEST_RESULT.json signals[] | M11: BT:DALBHARAT#e0d1of1 (git commit N/A) | N11: 0 | O11: 1/1 | P11: New
A12: 2025-10-03 | B12: DELHIVERY | C12: Delhivery Limited | D12: 437.3 | E12: N/A | F12: 66.13 | G12: N/A | H12: N/A | I12: 15770000 | J12: 2116500 | K12: ACCUMULATION CONFIRMED (engine verdict; per-gate values not stored) | L12: RECORDED: backtest/REAL_1YEAR_BACKTEST_RESULT.json signals[] | M12: BT:DELHIVERY#e0d1of1 (git commit N/A) | N12: 0 | O12: 1/1 | P12: New
A13: 2025-10-03 | B13: DIVISLAB | C13: Divi's Laboratories Limited | D13: 5866 | E13: N/A | F13: 61.94 | G13: N/A | H13: N/A | I13: 2673600 | J13: 5100 | K13: ACCUMULATION CONFIRMED (engine verdict; per-gate values not stored) | L13: RECORDED: backtest/REAL_1YEAR_BACKTEST_RESULT.json signals[] | M13: BT:DIVISLAB#e0d2of2 (git commit N/A) | N13: 0 | O13: 2/2 | P13: Active
... A853: 2026-09-03 | B853: SWIGGY | C853: Swiggy Limited | D853: 269.3 | E853: N/A | F853: 62.33 | G853: N/A | H853: N/A | I853: 87054325 | J853: 10521125 | K853: ACCUMULATION CONFIRMED (engine verdict; per-gate values not stored) | L853: RECORDED: backtest/REAL_1YEAR_BACKTEST_RESULT.json signals[] | M853: BT:SWIGGY#e1d1of1 (git commit N/A) | N853: 1 | O853: 1/1 | P853: New

Sheet T2_CatchToCurrent
A1: Catch Date | B1: Symbol | C1: Catch Price | D1: Latest/Current Verified Price | E1: Current Price Date | F1: Absolute Price Change | G1: Percentage Change (%) | H1: Status | I1: Corporate-action note | J1: Event Index
A2: 2025-10-01 | B2: APLAPOLLO | C2: 1731.1 | D2: 2197 | E2: 2026-09-28 | F2: =IF(AND(ISNUMBER(C2),ISNUMBER(D2)),D2-C2,"N/A") -> 465.9 | G2: =IF(ISNUMBER(F2),F2/C2*100,"N/A") -> 26.913523 | H2: =IF(NOT(ISNUMBER(F2)),"NO CURRENT DATA",IF(F2>0,"RISEN",IF(F2<0,"FALLEN","UNCHANGED"))) -> RISEN | I2: CORPORATE ACTION STATUS UNKNOWN (no heuristic flag) | J2: 0
A3: 2025-10-01 | B3: DIVISLAB | C3: 5710 | D3: 9550 | E3: 2026-09-28 | F3: =IF(AND(ISNUMBER(C3),ISNUMBER(D3)),D3-C3,"N/A") -> 3840 | G3: =IF(ISNUMBER(F3),F3/C3*100,"N/A") -> 67.250438 | H3: =IF(NOT(ISNUMBER(F3)),"NO CURRENT DATA",IF(F3>0,"RISEN",IF(F3<0,"FALLEN","UNCHANGED"))) -> RISEN | I3: CORPORATE ACTION STATUS UNKNOWN (no heuristic flag) | J3: 0
A4: 2025-10-01 | B4: FORTIS | C4: 989.65 | D4: 830.75 | E4: 2026-09-28 | F4: =IF(AND(ISNUMBER(C4),ISNUMBER(D4)),D4-C4,"N/A") -> -158.9 | G4: =IF(ISNUMBER(F4),F4/C4*100,"N/A") -> -16.056181 | H4: =IF(NOT(ISNUMBER(F4)),"NO CURRENT DATA",IF(F4>0,"RISEN",IF(F4<0,"FALLEN","UNCHANGED"))) -> FALLEN | I4: CORPORATE ACTION STATUS UNKNOWN (no heuristic flag) | J4: 0
A5: 2025-10-01 | B5: ICICIGI | C5: 1903.6 | D5: 1540 | E5: 2026-09-28 | F5: =IF(AND(ISNUMBER(C5),ISNUMBER(D5)),D5-C5,"N/A") -> -363.6 | G5: =IF(ISNUMBER(F5),F5/C5*100,"N/A") -> -19.100651 | H5: =IF(NOT(ISNUMBER(F5)),"NO CURRENT DATA",IF(F5>0,"RISEN",IF(F5<0,"FALLEN","UNCHANGED"))) -> FALLEN | I5: CORPORATE ACTION STATUS UNKNOWN (no heuristic flag) | J5: 0
A6: 2025-10-01 | B6: IEX | C6: 141.18 | D6: 111.35 | E6: 2026-09-28 | F6: =IF(AND(ISNUMBER(C6),ISNUMBER(D6)),D6-C6,"N/A") -> -29.83 | G6: =IF(ISNUMBER(F6),F6/C6*100,"N/A") -> -21.129055 | H6: =IF(NOT(ISNUMBER(F6)),"NO CURRENT DATA",IF(F6>0,"RISEN",IF(F6<0,"FALLEN","UNCHANGED"))) -> FALLEN | I6: CORPORATE ACTION STATUS UNKNOWN (no heuristic flag) | J6: 0
A7: 2025-10-01 | B7: MFSL | C7: 1621.9 | D7: 1444 | E7: 2026-09-28 | F7: =IF(AND(ISNUMBER(C7),ISNUMBER(D7)),D7-C7,"N/A") -> -177.9 | G7: =IF(ISNUMBER(F7),F7/C7*100,"N/A") -> -10.968617 | H7: =IF(NOT(ISNUMBER(F7)),"NO CURRENT DATA",IF(F7>0,"RISEN",IF(F7<0,"FALLEN","UNCHANGED"))) -> FALLEN | I7: CORPORATE ACTION STATUS UNKNOWN (no heuristic flag) | J7: 0
A8: 2025-10-01 | B8: SRF | C8: 2907.1 | D8: 2491.5 | E8: 2026-09-28 | F8: =IF(AND(ISNUMBER(C8),ISNUMBER(D8)),D8-C8,"N/A") -> -415.6 | G8: =IF(ISNUMBER(F8),F8/C8*100,"N/A") -> -14.296034 | H8: =IF(NOT(ISNUMBER(F8)),"NO CURRENT DATA",IF(F8>0,"RISEN",IF(F8<0,"FALLEN","UNCHANGED"))) -> FALLEN | I8: CORPORATE ACTION STATUS UNKNOWN (no heuristic flag) | J8: 0
A9: 2025-10-01 | B9: YESBANK | C9: 21.76 | D9: 21.18 | E9: 2026-09-28 | F9: =IF(AND(ISNUMBER(C9),ISNUMBER(D9)),D9-C9,"N/A") -> -0.58 | G9: =IF(ISNUMBER(F9),F9/C9*100,"N/A") -> -2.6654412 | H9: =IF(NOT(ISNUMBER(F9)),"NO CURRENT DATA",IF(F9>0,"RISEN",IF(F9<0,"FALLEN","UNCHANGED"))) -> FALLEN | I9: CORPORATE ACTION STATUS UNKNOWN (no heuristic flag) | J9: 0
A10: 2025-10-03 | B10: BAJAJ-AUTO | C10: 8679.5 | D10: 11024 | E10: 2026-09-28 | F10: =IF(AND(ISNUMBER(C10),ISNUMBER(D10)),D10-C10,"N/A") -> 2344.5 | G10: =IF(ISNUMBER(F10),F10/C10*100,"N/A") -> 27.011925 | H10: =IF(NOT(ISNUMBER(F10)),"NO CURRENT DATA",IF(F10>0,"RISEN",IF(F10<0,"FALLEN","UNCHANGED"))) -> RISEN | I10: CORPORATE ACTION STATUS UNKNOWN (no heuristic flag) | J10: 0
A11: 2025-10-03 | B11: DALBHARAT | C11: 2253.7 | D11: 1651.6 | E11: 2026-09-28 | F11: =IF(AND(ISNUMBER(C11),ISNUMBER(D11)),D11-C11,"N/A") -> -602.1 | G11: =IF(ISNUMBER(F11),F11/C11*100,"N/A") -> -26.716067 | H11: =IF(NOT(ISNUMBER(F11)),"NO CURRENT DATA",IF(F11>0,"RISEN",IF(F11<0,"FALLEN","UNCHANGED"))) -> FALLEN | I11: CORPORATE ACTION STATUS UNKNOWN (no heuristic flag) | J11: 0
A12: 2025-10-03 | B12: DELHIVERY | C12: 437.3 | D12: 407.5 | E12: 2026-09-28 | F12: =IF(AND(ISNUMBER(C12),ISNUMBER(D12)),D12-C12,"N/A") -> -29.8 | G12: =IF(ISNUMBER(F12),F12/C12*100,"N/A") -> -6.8145438 | H12: =IF(NOT(ISNUMBER(F12)),"NO CURRENT DATA",IF(F12>0,"RISEN",IF(F12<0,"FALLEN","UNCHANGED"))) -> FALLEN | I12: CORPORATE ACTION STATUS UNKNOWN (no heuristic flag) | J12: 0
A13: 2025-10-03 | B13: DIVISLAB | C13: 5866 | D13: 9550 | E13: 2026-09-28 | F13: =IF(AND(ISNUMBER(C13),ISNUMBER(D13)),D13-C13,"N/A") -> 3684 | G13: =IF(ISNUMBER(F13),F13/C13*100,"N/A") -> 62.802591 | H13: =IF(NOT(ISNUMBER(F13)),"NO CURRENT DATA",IF(F13>0,"RISEN",IF(F13<0,"FALLEN","UNCHANGED"))) -> RISEN | I13: CORPORATE ACTION STATUS UNKNOWN (no heuristic flag) | J13: 0
... A45: 2025-10-10 | B45: IDFCFIRSTB | C45: 74.43 | D45: 80.55 | E45: 2026-09-28 | F45: =IF(AND(ISNUMBER(C45),ISNUMBER(D45)),D45-C45,"N/A") -> 6.12 | G45: =IF(ISNUMBER(F45),F45/C45*100,"N/A") -> 8.2224909 | H45: =IF(NOT(ISNUMBER(F45)),"NO CURRENT DATA",IF(F45>0,"RISEN",IF(F45<0,"FALLEN","UNCHANGED"))) -> RISEN | I45: CORPORATE ACTION STATUS UNKNOWN (no heuristic flag) | J45: 0
A46: 2025-10-10 | B46: LTIM | C46: 5471.5 | D46: N/A | E46: N/A | F46: =IF(AND(ISNUMBER(C46),ISNUMBER(D46)),D46-C46,"N/A") -> N/A | G46: =IF(ISNUMBER(F46),F46/C46*100,"N/A") -> N/A | H46: =IF(NOT(ISNUMBER(F46)),"NO CURRENT DATA",IF(F46>0,"RISEN",IF(F46<0,"FALLEN","UNCHANGED"))) -> NO CURRENT DATA | I46: NO PRICE AT LATEST SESSION (symbol absent) — CORPORATE ACTION STATUS UNKNOWN | J46: 0
A47: 2025-10-10 | B47: TATAPOWER | C47: 390.1 | D47: 361.9 | E47: 2026-09-28 | F47: =IF(AND(ISNUMBER(C47),ISNUMBER(D47)),D47-C47,"N/A") -> -28.2 | G47: =IF(ISNUMBER(F47),F47/C47*100,"N/A") -> -7.2289157 | H47: =IF(NOT(ISNUMBER(F47)),"NO CURRENT DATA",IF(F47>0,"RISEN",IF(F47<0,"FALLEN","UNCHANGED"))) -> FALLEN | I47: CORPORATE ACTION STATUS UNKNOWN (no heuristic flag) | J47: 0
A48: 2025-10-13 | B48: DIVISLAB | C48: 6556 | D48: 9550 | E48: 2026-09-28 | F48: =IF(AND(ISNUMBER(C48),ISNUMBER(D48)),D48-C48,"N/A") -> 2994 | G48: =IF(ISNUMBER(F48),F48/C48*100,"N/A") -> 45.66809 | H48: =IF(NOT(ISNUMBER(F48)),"NO CURRENT DATA",IF(F48>0,"RISEN",IF(F48<0,"FALLEN","UNCHANGED"))) -> RISEN | I48: CORPORATE ACTION STATUS UNKNOWN (no heuristic flag) | J48: 1
A49: 2025-10-13 | B49: FEDERALBNK | C49: 213.02 | D49: 325 | E49: 2026-09-28 | F49: =IF(AND(ISNUMBER(C49),ISNUMBER(D49)),D49-C49,"N/A") -> 111.98 | G49: =IF(ISNUMBER(F49),F49/C49*100,"N/A") -> 52.567834 | H49: =IF(NOT(ISNUMBER(F49)),"NO CURRENT DATA",IF(F49>0,"RISEN",IF(F49<0,"FALLEN","UNCHANGED"))) -> RISEN | I49: CORPORATE ACTION STATUS UNKNOWN (no heuristic flag) | J49: 0
A50: 2025-10-14 | B50: BIOCON | C50: 351.85 | D50: 374.9 | E50: 2026-09-28 | F50: =IF(AND(ISNUMBER(C50),ISNUMBER(D50)),D50-C50,"N/A") -> 23.05 | G50: =IF(ISNUMBER(F50),F50/C50*100,"N/A") -> 6.5510871 | H50: =IF(NOT(ISNUMBER(F50)),"NO CURRENT DATA",IF(F50>0,"RISEN",IF(F50<0,"FALLEN","UNCHANGED"))) -> RISEN | I50: CORPORATE ACTION STATUS UNKNOWN (no heuristic flag) | J50: 0
A51: 2025-10-14 | B51: FEDERALBNK | C51: 215.44 | D51: 325 | E51: 2026-09-28 | F51: =IF(AND(ISNUMBER(C51),ISNUMBER(D51)),D51-C51,"N/A") -> 109.56 | G51: =IF(ISNUMBER(F51),F51/C51*100,"N/A") -> 50.854066 | H51: =IF(NOT(ISNUMBER(F51)),"NO CURRENT DATA",IF(F51>0,"RISEN",IF(F51<0,"FALLEN","UNCHANGED"))) -> RISEN | I51: CORPORATE ACTION STATUS UNKNOWN (no heuristic flag) | J51: 0
A52: 2025-10-14 | B52: LAURUSLABS | C52: 877.95 | D52: 2010.7 | E52: 2026-09-28 | F52: =IF(AND(ISNUMBER(C52),ISNUMBER(D52)),D52-C52,"N/A") -> 1132.75 | G52: =IF(ISNUMBER(F52),F52/C52*100,"N/A") -> 129.02215 | H52: =IF(NOT(ISNUMBER(F52)),"NO CURRENT DATA",IF(F52>0,"RISEN",IF(F52<0,"FALLEN","UNCHANGED"))) -> RISEN | I52: CORPORATE ACTION STATUS UNKNOWN (no heuristic flag) | J52: 0
A53: 2025-10-15 | B53: 360ONE | C53: 1160.4 | D53: 1045 | E53: 2026-09-28 | F53: =IF(AND(ISNUMBER(C53),ISNUMBER(D53)),D53-C53,"N/A") -> -115.4 | G53: =IF(ISNUMBER(F53),F53/C53*100,"N/A") -> -9.9448466 | H53: =IF(NOT(ISNUMBER(F53)),"NO CURRENT DATA",IF(F53>0,"RISEN",IF(F53<0,"FALLEN","UNCHANGED"))) -> FALLEN | I53: CORPORATE ACTION STATUS UNKNOWN (no heuristic flag) | J53: 0
A54: 2025-10-15 | B54: BAJAJFINSV | C54: 2084.1 | D54: 1752 | E54: 2026-09-28 | F54: =IF(AND(ISNUMBER(C54),ISNUMBER(D54)),D54-C54,"N/A") -> -332.1 | G54: =IF(ISNUMBER(F54),F54/C54*100,"N/A") -> -15.934936 | H54: =IF(NOT(ISNUMBER(F54)),"NO CURRENT DATA",IF(F54>0,"RISEN",IF(F54<0,"FALLEN","UNCHANGED"))) -> FALLEN | I54: CORPORATE ACTION STATUS UNKNOWN (no heuristic flag) | J54: 0
A55: 2025-10-15 | B55: BAJFINANCE | C55: 1059.9 | D55: 985 | E55: 2026-09-28 | F55: =IF(AND(ISNUMBER(C55),ISNUMBER(D55)),D55-C55,"N/A") -> -74.9 | G55: =IF(ISNUMBER(F55),F55/C55*100,"N/A") -> -7.0667044 | H55: =IF(NOT(ISNUMBER(F55)),"NO CURRENT DATA",IF(F55>0,"RISEN",IF(F55<0,"FALLEN","UNCHANGED"))) -> FALLEN | I55: CORPORATE ACTION STATUS UNKNOWN (no heuristic flag) | J55: 0
A56: 2025-10-15 | B56: CIPLA | C56: 1558.7 | D56: 1383.7 | E56: 2026-09-28 | F56: =IF(AND(ISNUMBER(C56),ISNUMBER(D56)),D56-C56,"N/A") -> -175 | G56: =IF(ISNUMBER(F56),F56/C56*100,"N/A") -> -11.227305 | H56: =IF(NOT(ISNUMBER(F56)),"NO CURRENT DATA",IF(F56>0,"RISEN",IF(F56<0,"FALLEN","UNCHANGED"))) -> FALLEN | I56: CORPORATE ACTION STATUS UNKNOWN (no heuristic flag) | J56: 0
A57: 2025-10-15 | B57: HINDALCO | C57: 764.25 | D57: 955.9 | E57: 2026-09-28 | F57: =IF(AND(ISNUMBER(C57),ISNUMBER(D57)),D57-C57,"N/A") -> 191.65 | G57: =IF(ISNUMBER(F57),F57/C57*100,"N/A") -> 25.076873 | H57: =IF(NOT(ISNUMBER(F57)),"NO CURRENT DATA",IF(F57>0,"RISEN",IF(F57<0,"FALLEN","UNCHANGED"))) -> RISEN | I57: CORPORATE ACTION STATUS UNKNOWN (no heuristic flag) | J57: 1
A58: 2025-10-15 | B58: HINDPETRO | C58: 448.65 | D58: 342.45 | E58: 2026-09-28 | F58: =IF(AND(ISNUMBER(C58),ISNUMBER(D58)),D58-C58,"N/A") -> -106.2 | G58: =IF(ISNUMBER(F58),F58/C58*100,"N/A") -> -23.671013 | H58: =IF(NOT(ISNUMBER(F58)),"NO CURRENT DATA",IF(F58>0,"RISEN",IF(F58<0,"FALLEN","UNCHANGED"))) -> FALLEN | I58: CORPORATE ACTION STATUS UNKNOWN (no heuristic flag) | J58: 1
... A119: 2025-11-12 | B119: ICICIPRULI | C119: 632.95 | D119: 458.7 | E119: 2026-09-28 | F119: =IF(AND(ISNUMBER(C119),ISNUMBER(D119)),D119-C119,"N/A") -> -174.25 | G119: =IF(ISNUMBER(F119),F119/C119*100,"N/A") -> -27.529821 | H119: =IF(NOT(ISNUMBER(F119)),"NO CURRENT DATA",IF(F119>0,"RISEN",IF(F119<0,"FALLEN","UNCHANGED"))) -> FALLEN | I119: CORPORATE ACTION STATUS UNKNOWN (no heuristic flag) | J119: 0
A120: 2025-11-12 | B120: LTIM | C120: 5893.5 | D120: N/A | E120: N/A | F120: =IF(AND(ISNUMBER(C120),ISNUMBER(D120)),D120-C120,"N/A") -> N/A | G120: =IF(ISNUMBER(F120),F120/C120*100,"N/A") -> N/A | H120: =IF(NOT(ISNUMBER(F120)),"NO CURRENT DATA",IF(F120>0,"RISEN",IF(F120<0,"FALLEN","UNCHANGED"))) -> NO CURRENT DATA | I120: NO PRICE AT LATEST SESSION (symbol absent) — CORPORATE ACTION STATUS UNKNOWN | J120: 1
A121: 2025-11-12 | B121: MOTHERSON | C121: 105.92 | D121: 162.37 | E121: 2026-09-28 | F121: =IF(AND(ISNUMBER(C121),ISNUMBER(D121)),D121-C121,"N/A") -> 56.45 | G121: =IF(ISNUMBER(F121),F121/C121*100,"N/A") -> 53.29494 | H121: =IF(NOT(ISNUMBER(F121)),"NO CURRENT DATA",IF(F121>0,"RISEN",IF(F121<0,"FALLEN","UNCHANGED"))) -> RISEN | I121: CORPORATE ACTION STATUS UNKNOWN (no heuristic flag) | J121: 0
A122: 2025-11-12 | B122: SRF | C122: 2941.4 | D122: 2491.5 | E122: 2026-09-28 | F122: =IF(AND(ISNUMBER(C122),ISNUMBER(D122)),D122-C122,"N/A") -> -449.9 | G122: =IF(ISNUMBER(F122),F122/C122*100,"N/A") -> -15.295438 | H122: =IF(NOT(ISNUMBER(F122)),"NO CURRENT DATA",IF(F122>0,"RISEN",IF(F122<0,"FALLEN","UNCHANGED"))) -> FALLEN | I122: CORPORATE ACTION STATUS UNKNOWN (no heuristic flag) | J122: 2
A123: 2025-11-12 | B123: SYNGENE | C123: 663.85 | D123: 376 | E123: 2026-09-28 | F123: =IF(AND(ISNUMBER(C123),ISNUMBER(D123)),D123-C123,"N/A") -> -287.85 | G123: =IF(ISNUMBER(F123),F123/C123*100,"N/A") -> -43.360699 | H123: =IF(NOT(ISNUMBER(F123)),"NO CURRENT DATA",IF(F123>0,"RISEN",IF(F123<0,"FALLEN","UNCHANGED"))) -> FALLEN | I123: CORPORATE ACTION STATUS UNKNOWN (no heuristic flag) | J123: 0
A124: 2025-11-13 | B124: GLENMARK | C124: 1880.6 | D124: 2325.7 | E124: 2026-09-28 | F124: =IF(AND(ISNUMBER(C124),ISNUMBER(D124)),D124-C124,"N/A") -> 445.1 | G124: =IF(ISNUMBER(F124),F124/C124*100,"N/A") -> 23.667978 | H124: =IF(NOT(ISNUMBER(F124)),"NO CURRENT DATA",IF(F124>0,"RISEN",IF(F124<0,"FALLEN","UNCHANGED"))) -> RISEN | I124: CORPORATE ACTION STATUS UNKNOWN (no heuristic flag) | J124: 1
A125: 2025-11-13 | B125: NMDC | C125: 77.39 | D125: 77.43 | E125: 2026-09-28 | F125: =IF(AND(ISNUMBER(C125),ISNUMBER(D125)),D125-C125,"N/A") -> 0.04 | G125: =IF(ISNUMBER(F125),F125/C125*100,"N/A") -> 0.051686264 | H125: =IF(NOT(ISNUMBER(F125)),"NO CURRENT DATA",IF(F125>0,"RISEN",IF(F125<0,"FALLEN","UNCHANGED"))) -> RISEN | I125: CORPORATE ACTION STATUS UNKNOWN (no heuristic flag) | J125: 1
A126: 2025-11-14 | B126: ASIANPAINT | C126: 2906.4 | D126: 2420 | E126: 2026-09-28 | F126: =IF(AND(ISNUMBER(C126),ISNUMBER(D126)),D126-C126,"N/A") -> -486.4 | G126: =IF(ISNUMBER(F126),F126/C126*100,"N/A") -> -16.73548 | H126: =IF(NOT(ISNUMBER(F126)),"NO CURRENT DATA",IF(F126>0,"RISEN",IF(F126<0,"FALLEN","UNCHANGED"))) -> FALLEN | I126: CORPORATE ACTION STATUS UNKNOWN (no heuristic flag) | J126: 1
A127: 2025-11-14 | B127: AUROPHARMA | C127: 1222.5 | D127: 1697.5 | E127: 2026-09-28 | F127: =IF(AND(ISNUMBER(C127),ISNUMBER(D127)),D127-C127,"N/A") -> 475 | G127: =IF(ISNUMBER(F127),F127/C127*100,"N/A") -> 38.854806 | H127: =IF(NOT(ISNUMBER(F127)),"NO CURRENT DATA",IF(F127>0,"RISEN",IF(F127<0,"FALLEN","UNCHANGED"))) -> RISEN | I127: CORPORATE ACTION STATUS UNKNOWN (no heuristic flag) | J127: 0
A128: 2025-11-14 | B128: GLENMARK | C128: 1895.6 | D128: 2325.7 | E128: 2026-09-28 | F128: =IF(AND(ISNUMBER(C128),ISNUMBER(D128)),D128-C128,"N/A") -> 430.1 | G128: =IF(ISNUMBER(F128),F128/C128*100,"N/A") -> 22.689386 | H128: =IF(NOT(ISNUMBER(F128)),"NO CURRENT DATA",IF(F128>0,"RISEN",IF(F128<0,"FALLEN","UNCHANGED"))) -> RISEN | I128: CORPORATE ACTION STATUS UNKNOWN (no heuristic flag) | J128: 1
A129: 2025-11-14 | B129: SIEMENS | C129: 3084.2 | D129: 3785.5 | E129: 2026-09-28 | F129: =IF(AND(ISNUMBER(C129),ISNUMBER(D129)),D129-C129,"N/A") -> 701.3 | G129: =IF(ISNUMBER(F129),F129/C129*100,"N/A") -> 22.738474 | H129: =IF(NOT(ISNUMBER(F129)),"NO CURRENT DATA",IF(F129>0,"RISEN",IF(F129<0,"FALLEN","UNCHANGED"))) -> RISEN | I129: CORPORATE ACTION STATUS UNKNOWN (no heuristic flag) | J129: 0
A130: 2025-11-17 | B130: POLICYBZR | C130: 1815.7 | D130: 1151.3 | E130: 2026-09-28 | F130: =IF(AND(ISNUMBER(C130),ISNUMBER(D130)),D130-C130,"N/A") -> -664.4 | G130: =IF(ISNUMBER(F130),F130/C130*100,"N/A") -> -36.591948 | H130: =IF(NOT(ISNUMBER(F130)),"NO CURRENT DATA",IF(F130>0,"RISEN",IF(F130<0,"FALLEN","UNCHANGED"))) -> FALLEN | I130: SUSPECTED discontinuity (heuristic ≥20% 1-day move): 2026-09-24 (-36.0%) — CORPORATE ACTION STATUS UNKNOWN | J130: 0
A131: 2025-11-18 | B131: CONCOR | C131: 522.6 | D131: 450 | E131: 2026-09-28 | F131: =IF(AND(ISNUMBER(C131),ISNUMBER(D131)),D131-C131,"N/A") -> -72.6 | G131: =IF(ISNUMBER(F131),F131/C131*100,"N/A") -> -13.892078 | H131: =IF(NOT(ISNUMBER(F131)),"NO CURRENT DATA",IF(F131>0,"RISEN",IF(F131<0,"FALLEN","UNCHANGED"))) -> FALLEN | I131: CORPORATE ACTION STATUS UNKNOWN (no heuristic flag) | J131: 1
...

Sheet T3_StockFrequency
A1: Symbol | B1: Company Name | C1: First Catch Date | D1: Last Catch Date | E1: Total Confirmed Catches (catch-days) | F1: Distinct Events | G1: All Catch Dates | H1: Catch Frequency | I1: Current/Latest Price | J1: Latest Price Date | K1: Latest Return % (last catch → current) | L1: Status (last catch) | M1: Avg Return % across all catches | N1: Catches Risen | O1: Catches Fallen
A2: 360ONE | B2: 360 ONE WAM LIMITED | C2: 2025-10-15 | D2: 2026-08-05 | E2: 10 | F2: 10 | G2: 2025-10-15; 2026-04-09; 2026-04-15; 2026-04-17; 2026-05-04; 2026-05-06; 2026-06-15; 2026-06-19; 2026-07-10; 2026-08-05 | H2: 10 catch-days in 10 event(s); 4.37 per 100 evaluated sessions (229 evaluated) | I2: 1045 | J2: 2026-09-28 | K2: -12.332215 | L2: FALLEN | M2: -5.4146688 | N2: 1 | O2: 9
A3: ABB | B3: ABB India Limited | C3: 2026-02-03 | D3: 2026-04-15 | E3: 5 | F3: 3 | G3: 2026-02-03; 2026-04-08; 2026-04-09; 2026-04-10; 2026-04-15 | H3: 5 catch-days in 3 event(s); 2.18 per 100 evaluated sessions (229 evaluated) | I3: 6972.5 | J3: 2026-09-28 | K3: 1.4476939 | L3: RISEN | M3: 7.5453692 | N3: 5 | O3: 0
A4: ABCAPITAL | B4: Aditya Birla Capital Limited | C4: 2025-12-31 | D4: 2026-09-02 | E4: 3 | F4: 3 | G4: 2025-12-31; 2026-05-20; 2026-09-02 | H4: 3 catch-days in 3 event(s); 1.31 per 100 evaluated sessions (229 evaluated) | I4: 382.7 | J4: 2026-09-28 | K4: -3.6141544 | L4: FALLEN | M4: 3.919279 | N4: 2 | O4: 1
A5: ADANIENSOL | B5: Adani Energy Solutions Limited | C5: 2026-04-17 | D5: 2026-08-14 | E5: 2 | F5: 2 | G5: 2026-04-17; 2026-08-14 | H5: 2 catch-days in 2 event(s); 0.87 per 100 evaluated sessions (229 evaluated) | I5: 1287.9 | J5: 2026-09-28 | K5: -20.303218 | L5: FALLEN | M5: -9.0363525 | N5: 1 | O5: 1
A6: ADANIENT | B6: Adani Enterprises Limited | C6: 2025-12-04 | D6: 2026-07-01 | E6: 2 | F6: 2 | G6: 2025-12-04; 2026-07-01 | H6: 2 catch-days in 2 event(s); 0.87 per 100 evaluated sessions (229 evaluated) | I6: 2831.1 | J6: 2026-09-28 | K6: -9.9408322 | L6: FALLEN | M6: 8.8534714 | N6: 1 | O6: 1
A7: ADANIPORTS | B7: Adani Ports and Special Economic Zone Limited | C7: 2025-10-16 | D7: 2026-06-17 | E7: 3 | F7: 3 | G7: 2025-10-16; 2026-04-01; 2026-06-17 | H7: 3 catch-days in 3 event(s); 1.31 per 100 evaluated sessions (229 evaluated) | I7: 1743.7 | J7: 2026-09-28 | K7: -4.6428962 | L7: FALLEN | M7: 13.025685 | N7: 2 | O7: 1
A8: ADANIPOWER | B8: Adani Power Limited | C8: 2026-04-06 | D8: 2026-04-06 | E8: 1 | F8: 1 | G8: 2026-04-06 | H8: 1 catch-days in 1 event(s); 0.44 per 100 evaluated sessions (229 evaluated) | I8: 196.14 | J8: 2026-09-28 | K8: 20.139655 | L8: RISEN | M8: 20.139655 | N8: 1 | O8: 0
A9: ALKEM | B9: Alkem Laboratories Limited | C9: 2025-11-07 | D9: 2026-08-28 | E9: 12 | F9: 11 | G9: 2025-11-07; 2026-01-07; 2026-01-12; 2026-02-09; 2026-04-15; 2026-05-29; 2026-06-30; 2026-07-03; 2026-07-07; 2026-07-14; 2026-08-27; 2026-08-28 | H9: 12 catch-days in 11 event(s); 5.24 per 100 evaluated sessions (229 evaluated) | I9: 5175 | J9: 2026-09-28 | K9: -3.3613445 | L9: FALLEN | M9: -7.5742607 | N9: 0 | O9: 12
A10: AMBER | B10: Amber Enterprises India Limited | C10: 2026-08-18 | D10: 2026-08-18 | E10: 1 | F10: 1 | G10: 2026-08-18 | H10: 1 catch-days in 1 event(s); 0.44 per 100 evaluated sessions (229 evaluated) | I10: 6990 | J10: 2026-09-28 | K10: -4.8979592 | L10: FALLEN | M10: -4.8979592 | N10: 0 | O10: 1
A11: AMBUJACEM | B11: Ambuja Cements Limited | C11: 2025-12-11 | D11: 2026-08-05 | E11: 3 | F11: 3 | G11: 2025-12-11; 2026-01-29; 2026-08-05 | H11: 3 catch-days in 3 event(s); 1.31 per 100 evaluated sessions (229 evaluated) | I11: 374.35 | J11: 2026-09-28 | K11: -15.876404 | L11: FALLEN | M11: -25.40437 | N11: 0 | O11: 3
A12: APLAPOLLO | B12: APL Apollo Tubes Limited | C12: 2025-10-01 | D12: 2026-08-28 | E12: 7 | F12: 7 | G12: 2025-10-01; 2025-12-17; 2026-01-01; 2026-01-14; 2026-06-15; 2026-08-03; 2026-08-28 | H12: 7 catch-days in 7 event(s); 3.06 per 100 evaluated sessions (229 evaluated) | I12: 2197 | J12: 2026-09-28 | K12: -3.0278955 | L12: FALLEN | M12: 15.206159 | N12: 6 | O12: 1
A13: APOLLOHOSP | B13: Apollo Hospitals Enterprise Limited | C13: 2026-01-07 | D13: 2026-07-09 | E13: 4 | F13: 4 | G13: 2026-01-07; 2026-02-06; 2026-06-09; 2026-07-09 | H13: 4 catch-days in 4 event(s); 1.75 per 100 evaluated sessions (229 evaluated) | I13: 8860 | J13: 2026-09-28 | K13: 0.16392516 | L13: RISEN | M13: 11.736151 | N13: 4 | O13: 0
... A108: LTF | B108: L&T Finance Limited | C108: 2025-10-03 | D108: 2026-05-29 | E108: 2 | F108: 2 | G108: 2025-10-03; 2026-05-29 | H108: 2 catch-days in 2 event(s); 0.87 per 100 evaluated sessions (229 evaluated) | I108: 280.85 | J108: 2026-09-28 | K108: -2.0062805 | L108: FALLEN | M108: 2.5267648 | N108: 1 | O108: 1
A109: LTIM | B109: N/A | C109: 2025-10-10 | D109: 2026-01-16 | E109: 4 | F109: 4 | G109: 2025-10-10; 2025-11-12; 2025-12-17; 2026-01-16 | H109: 4 catch-days in 4 event(s); 3.92 per 100 evaluated sessions (102 evaluated) | I109: N/A | J109: N/A | K109: N/A | L109: NO CURRENT DATA | M109: N/A | N109: 0 | O109: 0
A110: LTM | B110: LTM Limited | C110: 2026-04-02 | D110: 2026-04-16 | E110: 3 | F110: 2 | G110: 2026-04-02; 2026-04-15; 2026-04-16 | H110: 3 catch-days in 2 event(s); 2.80 per 100 evaluated sessions (107 evaluated) | I110: 4091.4 | J110: 2026-09-28 | K110: -13.501057 | L110: FALLEN | M110: -10.015483 | N110: 0 | O110: 3
A111: LUPIN | B111: Lupin Limited | C111: 2025-10-31 | D111: 2026-07-29 | E111: 8 | F111: 6 | G111: 2025-10-31; 2025-11-03; 2025-11-04; 2026-01-06; 2026-02-25; 2026-03-10; 2026-05-06; 2026-07-29 | H111: 8 catch-days in 6 event(s); 3.49 per 100 evaluated sessions (229 evaluated) | I111: 2062 | J111: 2026-09-28 | K111: -15.733551 | L111: FALLEN | M111: -5.6271283 | N111: 3 | O111: 5
A112: MANAPPURAM | B112: Manappuram Finance Limited | C112: 2025-11-10 | D112: 2026-07-31 | E112: 4 | F112: 4 | G112: 2025-11-10; 2025-12-19; 2026-07-20; 2026-07-31 | H112: 4 catch-days in 4 event(s); 1.75 per 100 evaluated sessions (229 evaluated) | I112: 313 | J112: 2026-09-28 | K112: -15.826274 | L112: FALLEN | M112: -0.85290182 | N112: 2 | O112: 2
A113: MANKIND | B113: Mankind Pharma Limited | C113: 2025-10-06 | D113: 2026-05-15 | E113: 7 | F113: 7 | G113: 2025-10-06; 2025-10-17; 2025-12-12; 2026-02-03; 2026-02-25; 2026-05-11; 2026-05-15 | H113: 7 catch-days in 7 event(s); 3.06 per 100 evaluated sessions (229 evaluated) | I113: 2435.6 | J113: 2026-09-28 | K113: -2.6927687 | L113: FALLEN | M113: 4.4083431 | N113: 3 | O113: 4
A114: MARICO | B114: Marico Limited | C114: 2026-04-01 | D114: 2026-08-03 | E114: 3 | F114: 2 | G114: 2026-04-01; 2026-04-02; 2026-08-03 | H114: 3 catch-days in 2 event(s); 1.31 per 100 evaluated sessions (229 evaluated) | I114: 813.25 | J114: 2026-09-28 | K114: -7.6848856 | L114: FALLEN | M114: 2.7887795 | N114: 2 | O114: 1
A115: MARUTI | B115: Maruti Suzuki India Limited | C115: 2025-12-30 | D115: 2026-06-30 | E115: 4 | F115: 4 | G115: 2025-12-30; 2026-05-07; 2026-06-12; 2026-06-30 | H115: 4 catch-days in 4 event(s); 1.75 per 100 evaluated sessions (229 evaluated) | I115: 12008 | J115: 2026-09-28 | K115: -14.927382 | L115: FALLEN | M115: -16.437577 | N115: 0 | O115: 4
A116: MAXHEALTH | B116: Max Healthcare Institute Limited | C116: 2026-02-10 | D116: 2026-03-20 | E116: 2 | F116: 2 | G116: 2026-02-10; 2026-03-20 | H116: 2 catch-days in 2 event(s); 0.87 per 100 evaluated sessions (229 evaluated) | I116: 1000.1 | J116: 2026-09-28 | K116: 3.6587894 | L116: RISEN | M116: 0.7819155 | N116: 1 | O116: 1
A117: MFSL | B117: Max Financial Services Limited | C117: 2025-10-01 | D117: 2026-07-29 | E117: 7 | F117: 7 | G117: 2025-10-01; 2025-11-04; 2026-01-06; 2026-02-09; 2026-02-13; 2026-03-20; 2026-07-29 | H117: 7 catch-days in 7 event(s); 3.06 per 100 evaluated sessions (229 evaluated) | I117: 1444 | J117: 2026-09-28 | K117: -4.6927596 | L117: FALLEN | M117: -13.14249 | N117: 0 | O117: 7
A118: MOTHERSON | B118: Samvardhana Motherson International Limited | C118: 2025-11-12 | D118: 2026-07-31 | E118: 8 | F118: 7 | G118: 2025-11-12; 2025-12-02; 2025-12-11; 2026-04-01; 2026-05-19; 2026-05-27; 2026-05-29; 2026-07-31 | H118: 8 catch-days in 7 event(s); 3.49 per 100 evaluated sessions (229 evaluated) | I118: 162.37 | J118: 2026-09-28 | K118: 7.708126 | L118: RISEN | M118: 29.05874 | N118: 8 | O118: 0
A119: MOTILALOFS | B119: Motilal Oswal Financial Services Limited | C119: 2026-07-09 | D119: 2026-07-09 | E119: 1 | F119: 1 | G119: 2026-07-09 | H119: 1 catch-days in 1 event(s); 0.44 per 100 evaluated sessions (229 evaluated) | I119: 1011.6 | J119: 2026-09-28 | K119: 7.331565 | L119: RISEN | M119: 7.331565 | N119: 1 | O119: 0
A120: MPHASIS | B120: MphasiS Limited | C120: 2025-10-29 | D120: 2026-08-28 | E120: 4 | F120: 4 | G120: 2025-10-29; 2026-05-29; 2026-06-17; 2026-08-28 | H120: 4 catch-days in 4 event(s); 1.75 per 100 evaluated sessions (229 evaluated) | I120: 2237.5 | J120: 2026-09-28 | K120: -8.8594705 | L120: FALLEN | M120: -9.2258849 | N120: 0 | O120: 4
A121: MUTHOOTFIN | B121: Muthoot Finance Limited | C121: 2026-01-05 | D121: 2026-07-31 | E121: 7 | F121: 6 | G121: 2026-01-05; 2026-01-06; 2026-02-03; 2026-05-13; 2026-05-29; 2026-07-06; 2026-07-31 | H121: 7 catch-days in 6 event(s); 3.06 per 100 evaluated sessions (229 evaluated) | I121: 2760 | J121: 2026-09-28 | K121: -11.527119 | L121: FALLEN | M121: -20.814611 | N121: 0 | O121: 7
... A193: ZYDUSLIFE | B193: Zydus Lifesciences Limited | C193: 2026-07-03 | D193: 2026-08-27 | E193: 2 | F193: 2 | G193: 2026-07-03; 2026-08-27 | H193: 2 catch-days in 2 event(s); 0.87 per 100 evaluated sessions (229 evaluated) | I193: 1215 | J193: 2026-09-28 | K193: 2.1695257 | L193: RISEN | M193: 4.3462042 | N193: 2 | O193: 0

Sheet T8_MostCaught
A1: Rank | B1: Symbol | C1: Company | D1: Number of Catches (catch-days) | E1: Distinct Events | F1: All Catch Dates | G1: First Catch | H1: Last Catch | I1: Latest Price | J1: Latest Return % (last catch → current)
A2: 1 | B2: IOC | C2: Indian Oil Corporation Limited | D2: 18 | E2: 15 | F2: 2025-10-06; 2025-10-09; 2025-10-15; 2025-11-11; 2025-12-12; 2025-12-17; 2025-12-31; 2026-01-28; 2026-02-02; 2026-02-03; 2026-02-04; 2026-02-25; 2026-02-27; 2026-06-15; 2026-07-02; 2026-07-07; 2026-07-15; 2026-07-16 | G2: 2025-10-06 | H2: 2026-07-16 | I2: 133.32 | J2: -5.9802539
A3: 2 | B3: DELHIVERY | C3: Delhivery Limited | D3: 15 | E3: 12 | F3: 2025-10-03; 2025-11-04; 2025-12-19; 2026-01-05; 2026-01-06; 2026-01-07; 2026-01-28; 2026-01-29; 2026-02-10; 2026-03-18; 2026-03-20; 2026-04-08; 2026-05-15; 2026-07-02; 2026-07-10 | G3: 2025-10-03 | H3: 2026-07-10 | I3: 407.5 | J3: -21.6798
A4: 3 | B4: ALKEM | C4: Alkem Laboratories Limited | D4: 12 | E4: 11 | F4: 2025-11-07; 2026-01-07; 2026-01-12; 2026-02-09; 2026-04-15; 2026-05-29; 2026-06-30; 2026-07-03; 2026-07-07; 2026-07-14; 2026-08-27; 2026-08-28 | G4: 2025-11-07 | H4: 2026-08-28 | I4: 5175 | J4: -3.3613445
A5: 4 | B5: DIVISLAB | C5: Divi's Laboratories Limited | D5: 12 | E5: 9 | F5: 2025-10-01; 2025-10-03; 2025-10-10; 2025-10-13; 2025-11-06; 2026-05-13; 2026-06-09; 2026-07-15; 2026-07-30; 2026-07-31; 2026-08-26; 2026-08-28 | G5: 2025-10-01 | H5: 2026-08-28 | I5: 9550 | J5: 3.3661652
A6: 5 | B6: BIOCON | C6: Biocon Limited | D6: 11 | E6: 10 | F6: 2025-10-14; 2025-10-29; 2025-10-30; 2025-11-03; 2025-11-06; 2026-01-07; 2026-02-03; 2026-02-25; 2026-05-11; 2026-05-14; 2026-07-03 | G6: 2025-10-14 | H6: 2026-07-03 | I6: 374.9 | J6: -12.160262
A7: 6 | B7: NTPC | C7: NTPC Limited | D7: 11 | E7: 8 | F7: 2025-10-29; 2026-01-28; 2026-01-29; 2026-02-04; 2026-02-23; 2026-02-24; 2026-03-06; 2026-03-12; 2026-04-08; 2026-04-09; 2026-08-05 | G7: 2025-10-29 | H7: 2026-08-05 | I7: 321.1 | J7: -8.2309231
A8: 7 | B8: TECHM | C8: Tech Mahindra Limited | D8: 11 | E8: 10 | F8: 2025-10-06; 2025-11-10; 2025-11-11; 2025-11-19; 2026-01-07; 2026-01-16; 2026-03-20; 2026-05-19; 2026-05-29; 2026-07-30; 2026-08-28 | G8: 2025-10-06 | H8: 2026-08-28 | I8: 1542.2 | J8: -6.0149918
A9: 8 | B9: 360ONE | C9: 360 ONE WAM LIMITED | D9: 10 | E9: 10 | F9: 2025-10-15; 2026-04-09; 2026-04-15; 2026-04-17; 2026-05-04; 2026-05-06; 2026-06-15; 2026-06-19; 2026-07-10; 2026-08-05 | G9: 2025-10-15 | H9: 2026-08-05 | I9: 1045 | J9: -12.332215
A10: 9 | B10: BRITANNIA | C10: Britannia Industries Limited | D10: 10 | E10: 7 | F10: 2025-11-06; 2025-11-07; 2026-01-05; 2026-01-06; 2026-01-30; 2026-02-11; 2026-04-08; 2026-07-01; 2026-07-02; 2026-07-29 | G10: 2025-11-06 | H10: 2026-07-29 | I10: 4915 | J10: -10.919801
A11: 10 | B11: ICICIPRULI | C11: ICICI Prudential Life Insurance Company Limited | D11: 10 | E11: 10 | F11: 2025-11-12; 2025-12-10; 2025-12-18; 2025-12-31; 2026-01-16; 2026-04-01; 2026-04-17; 2026-06-22; 2026-07-10; 2026-08-31 | G11: 2025-11-12 | H11: 2026-08-31 | I11: 458.7 | J11: -11.285176
A12: 11 | B12: PHOENIXLTD | C12: The Phoenix Mills Limited | D12: 10 | E12: 9 | F12: 2025-10-16; 2025-12-15; 2026-01-05; 2026-01-06; 2026-03-18; 2026-04-10; 2026-04-21; 2026-06-10; 2026-06-15; 2026-07-03 | G12: 2025-10-16 | H12: 2026-07-03 | I12: 1952.2 | J12: -4.6591131
A13: 12 | B13: PIDILITIND | C13: Pidilite Industries Limited | D13: 10 | E13: 9 | F13: 2025-10-08; 2025-10-17; 2026-01-05; 2026-02-04; 2026-04-10; 2026-05-07; 2026-06-12; 2026-06-15; 2026-07-15; 2026-07-17 | G13: 2025-10-08 | H13: 2026-07-17 | I13: 1503 | J13: -4.0291169
... A92: 91 | B92: LICI | C92: Life Insurance Corporation Of India | D92: 4 | E92: 3 | F92: 2025-11-03; 2025-12-18; 2026-08-11; 2026-08-12 | G92: 2025-11-03 | H92: 2026-08-12 | I92: 400.65 | J92: -3.9208633
A93: 92 | B93: LTIM | C93: N/A | D93: 4 | E93: 4 | F93: 2025-10-10; 2025-11-12; 2025-12-17; 2026-01-16 | G93: 2025-10-10 | H93: 2026-01-16 | I93: N/A | J93: N/A
A94: 93 | B94: MANAPPURAM | C94: Manappuram Finance Limited | D94: 4 | E94: 4 | F94: 2025-11-10; 2025-12-19; 2026-07-20; 2026-07-31 | G94: 2025-11-10 | H94: 2026-07-31 | I94: 313 | J94: -15.826274
A95: 94 | B95: MARUTI | C95: Maruti Suzuki India Limited | D95: 4 | E95: 4 | F95: 2025-12-30; 2026-05-07; 2026-06-12; 2026-06-30 | G95: 2025-12-30 | H95: 2026-06-30 | I95: 12008 | J95: -14.927382
A96: 95 | B96: MPHASIS | C96: MphasiS Limited | D96: 4 | E96: 4 | F96: 2025-10-29; 2026-05-29; 2026-06-17; 2026-08-28 | G96: 2025-10-29 | H96: 2026-08-28 | I96: 2237.5 | J96: -8.8594705
A97: 96 | B97: NESTLEIND | C97: Nestle India Limited | D97: 4 | E97: 4 | F97: 2026-01-05; 2026-03-10; 2026-04-01; 2026-08-31 | G97: 2026-01-05 | H97: 2026-08-31 | I97: 1346 | J97: -10.056799
A98: 97 | B98: NUVAMA | C98: Nuvama Wealth Management Limited | D98: 4 | E98: 4 | F98: 2025-11-28; 2026-03-18; 2026-05-05; 2026-05-07 | G98: 2025-11-28 | H98: 2026-05-07 | I98: 1640.6 | J98: 11.264836
A99: 98 | B99: PIIND | C99: PI Industries Limited | D99: 4 | E99: 4 | F99: 2026-03-20; 2026-04-15; 2026-04-17; 2026-08-05 | G99: 2026-03-20 | H99: 2026-08-05 | I99: 2349 | J99: -16.405694
A100: 99 | B100: RECLTD | C100: REC Limited | D100: 4 | E100: 3 | F100: 2026-01-06; 2026-03-17; 2026-03-18; 2026-07-29 | G100: 2026-01-06 | H100: 2026-07-29 | I100: 303.25 | J100: -18.971276
A101: 100 | B101: SAMMAANCAP | C101: Sammaan Capital Limited | D101: 4 | E101: 3 | F101: 2025-12-31; 2026-01-05; 2026-01-28; 2026-01-29 | G101: 2025-12-31 | H101: 2026-01-29 | I101: 138.82 | J101: -5.9293894
A102: 101 | B102: SHRIRAMFIN | C102: Shriram Finance Limited | D102: 4 | E102: 4 | F102: 2025-10-31; 2025-11-07; 2025-12-17; 2026-01-16 | G102: 2025-10-31 | H102: 2026-01-16 | I102: 976.3 | J102: -1.9237531
A103: 102 | B103: SUPREMEIND | C103: Supreme Industries Limited | D103: 4 | E103: 4 | F103: 2026-02-04; 2026-02-25; 2026-03-11; 2026-04-17 | G103: 2026-02-04 | H103: 2026-04-17 | I103: 3499.8 | J103: -5.6403343
A104: 103 | B104: TATAPOWER | C104: Tata Power Company Limited | D104: 4 | E104: 3 | F104: 2025-10-09; 2025-10-10; 2025-12-12; 2026-06-15 | G104: 2025-10-09 | H104: 2026-06-15 | I104: 361.9 | J104: -10.44296
A105: 104 | B105: TATASTEEL | C105: Tata Steel Limited | D105: 4 | E105: 3 | F105: 2026-07-31; 2026-08-03; 2026-08-10; 2026-08-26 | G105: 2026-07-31 | H105: 2026-08-26 | I105: 186.3 | J105: -0.90952609
... A193: 192 | B193: TRENT | C193: Trent Limited | D193: 1 | E193: 1 | F193: 2026-06-19 | G193: 2026-06-19 | H193: 2026-06-19 | I193: 2626 | J193: -18.085969

Sheet T4_Daily
A1: Date | B1: Total Stocks Scanned (derived) | C1: STARTING | D1: CONFIRMED (catch-days) | E1: Unique Confirmed | F1: Repeat Confirmations | G1: First-time Catches | H1: Confirmation Rate = CONFIRMED / STARTING | I1: Supplementary rate (denominator stated) | J1: Evidence Status
A2: 2025-09-02 | B2: MISSING / UNVERIFIED | C2: MISSING / UNVERIFIED | D2: MISSING / UNVERIFIED | E2: MISSING / UNVERIFIED | F2: MISSING / UNVERIFIED | G2: MISSING / UNVERIFIED | H2: MISSING / UNVERIFIED | I2: MISSING / UNVERIFIED | J2: MISSING / UNVERIFIED — warm-up: engine needs 20 prior sessions, no verdict possible
A3: 2025-09-03 | B3: MISSING / UNVERIFIED | C3: MISSING / UNVERIFIED | D3: MISSING / UNVERIFIED | E3: MISSING / UNVERIFIED | F3: MISSING / UNVERIFIED | G3: MISSING / UNVERIFIED | H3: MISSING / UNVERIFIED | I3: MISSING / UNVERIFIED | J3: MISSING / UNVERIFIED — warm-up: engine needs 20 prior sessions, no verdict possible
A4: 2025-09-04 | B4: MISSING / UNVERIFIED | C4: MISSING / UNVERIFIED | D4: MISSING / UNVERIFIED | E4: MISSING / UNVERIFIED | F4: MISSING / UNVERIFIED | G4: MISSING / UNVERIFIED | H4: MISSING / UNVERIFIED | I4: MISSING / UNVERIFIED | J4: MISSING / UNVERIFIED — warm-up: engine needs 20 prior sessions, no verdict possible
A5: 2025-09-05 | B5: MISSING / UNVERIFIED | C5: MISSING / UNVERIFIED | D5: MISSING / UNVERIFIED | E5: MISSING / UNVERIFIED | F5: MISSING / UNVERIFIED | G5: MISSING / UNVERIFIED | H5: MISSING / UNVERIFIED | I5: MISSING / UNVERIFIED | J5: MISSING / UNVERIFIED — warm-up: engine needs 20 prior sessions, no verdict possible
A6: 2025-09-08 | B6: MISSING / UNVERIFIED | C6: MISSING / UNVERIFIED | D6: MISSING / UNVERIFIED | E6: MISSING / UNVERIFIED | F6: MISSING / UNVERIFIED | G6: MISSING / UNVERIFIED | H6: MISSING / UNVERIFIED | I6: MISSING / UNVERIFIED | J6: MISSING / UNVERIFIED — warm-up: engine needs 20 prior sessions, no verdict possible
A7: 2025-09-09 | B7: MISSING / UNVERIFIED | C7: MISSING / UNVERIFIED | D7: MISSING / UNVERIFIED | E7: MISSING / UNVERIFIED | F7: MISSING / UNVERIFIED | G7: MISSING / UNVERIFIED | H7: MISSING / UNVERIFIED | I7: MISSING / UNVERIFIED | J7: MISSING / UNVERIFIED — warm-up: engine needs 20 prior sessions, no verdict possible
A8: 2025-09-10 | B8: MISSING / UNVERIFIED | C8: MISSING / UNVERIFIED | D8: MISSING / UNVERIFIED | E8: MISSING / UNVERIFIED | F8: MISSING / UNVERIFIED | G8: MISSING / UNVERIFIED | H8: MISSING / UNVERIFIED | I8: MISSING / UNVERIFIED | J8: MISSING / UNVERIFIED — warm-up: engine needs 20 prior sessions, no verdict possible
A9: 2025-09-11 | B9: MISSING / UNVERIFIED | C9: MISSING / UNVERIFIED | D9: MISSING / UNVERIFIED | E9: MISSING / UNVERIFIED | F9: MISSING / UNVERIFIED | G9: MISSING / UNVERIFIED | H9: MISSING / UNVERIFIED | I9: MISSING / UNVERIFIED | J9: MISSING / UNVERIFIED — warm-up: engine needs 20 prior sessions, no verdict possible
A10: 2025-09-12 | B10: MISSING / UNVERIFIED | C10: MISSING / UNVERIFIED | D10: MISSING / UNVERIFIED | E10: MISSING / UNVERIFIED | F10: MISSING / UNVERIFIED | G10: MISSING / UNVERIFIED | H10: MISSING / UNVERIFIED | I10: MISSING / UNVERIFIED | J10: MISSING / UNVERIFIED — warm-up: engine needs 20 prior sessions, no verdict possible
A11: 2025-09-15 | B11: MISSING / UNVERIFIED | C11: MISSING / UNVERIFIED | D11: MISSING / UNVERIFIED | E11: MISSING / UNVERIFIED | F11: MISSING / UNVERIFIED | G11: MISSING / UNVERIFIED | H11: MISSING / UNVERIFIED | I11: MISSING / UNVERIFIED | J11: MISSING / UNVERIFIED — warm-up: engine needs 20 prior sessions, no verdict possible
A12: 2025-09-16 | B12: MISSING / UNVERIFIED | C12: MISSING / UNVERIFIED | D12: MISSING / UNVERIFIED | E12: MISSING / UNVERIFIED | F12: MISSING / UNVERIFIED | G12: MISSING / UNVERIFIED | H12: MISSING / UNVERIFIED | I12: MISSING / UNVERIFIED | J12: MISSING / UNVERIFIED — warm-up: engine needs 20 prior sessions, no verdict possible
... A21: 2025-09-29 | B21: MISSING / UNVERIFIED | C21: MISSING / UNVERIFIED | D21: MISSING / UNVERIFIED | E21: MISSING / UNVERIFIED | F21: MISSING / UNVERIFIED | G21: MISSING / UNVERIFIED | H21: MISSING / UNVERIFIED | I21: MISSING / UNVERIFIED | J21: MISSING / UNVERIFIED — warm-up: engine needs 20 prior sessions, no verdict possible
A22: 2025-09-30 | B22: 2085 | C22: N/A (not stored) | D22: 0 | E22: 0 | F22: 0 | G22: 0 | H22: N/A — STARTING not recorded (CONFIRMED / STARTING) | I22: 0.000% (CONFIRMED / 2085 scanned) | J22: RECORDED — recorded engine run (REAL_1YEAR_BACKTEST_RESULT.json)
A23: 2025-10-01 | B23: 2087 | C23: N/A (not stored) | D23: 8 | E23: 8 | F23: 0 | G23: 8 | H23: N/A — STARTING not recorded (CONFIRMED / STARTING) | I23: 0.383% (CONFIRMED / 2087 scanned) | J23: RECORDED — recorded engine run (REAL_1YEAR_BACKTEST_RESULT.json)
A24: 2025-10-03 | B24: 2086 | C24: N/A (not stored) | D24: 14 | E24: 14 | F24: 2 | G24: 12 | H24: N/A — STARTING not recorded (CONFIRMED / STARTING) | I24: 0.671% (CONFIRMED / 2086 scanned) | J24: RECORDED — recorded engine run (REAL_1YEAR_BACKTEST_RESULT.json)
A25: 2025-10-06 | B25: 2086 | C25: N/A (not stored) | D25: 7 | E25: 7 | F25: 0 | G25: 7 | H25: N/A — STARTING not recorded (CONFIRMED / STARTING) | I25: 0.336% (CONFIRMED / 2086 scanned) | J25: RECORDED — recorded engine run (REAL_1YEAR_BACKTEST_RESULT.json)
A26: 2025-10-07 | B26: 2102 | C26: N/A (not stored) | D26: 5 | E26: 5 | F26: 2 | G26: 3 | H26: N/A — STARTING not recorded (CONFIRMED / STARTING) | I26: 0.238% (CONFIRMED / 2102 scanned) | J26: RECORDED — recorded engine run (REAL_1YEAR_BACKTEST_RESULT.json)
A27: 2025-10-08 | B27: 2170 | C27: N/A (not stored) | D27: 1 | E27: 1 | F27: 0 | G27: 1 | H27: N/A — STARTING not recorded (CONFIRMED / STARTING) | I27: 0.046% (CONFIRMED / 2170 scanned) | J27: RECORDED — recorded engine run (REAL_1YEAR_BACKTEST_RESULT.json)
A28: 2025-10-09 | B28: 2169 | C28: N/A (not stored) | D28: 5 | E28: 5 | F28: 1 | G28: 4 | H28: N/A — STARTING not recorded (CONFIRMED / STARTING) | I28: 0.231% (CONFIRMED / 2169 scanned) | J28: RECORDED — recorded engine run (REAL_1YEAR_BACKTEST_RESULT.json)
A29: 2025-10-10 | B29: 2166 | C29: N/A (not stored) | D29: 6 | E29: 6 | F29: 3 | G29: 3 | H29: N/A — STARTING not recorded (CONFIRMED / STARTING) | I29: 0.277% (CONFIRMED / 2166 scanned) | J29: RECORDED — recorded engine run (REAL_1YEAR_BACKTEST_RESULT.json)
A30: 2025-10-13 | B30: 2166 | C30: N/A (not stored) | D30: 2 | E30: 2 | F30: 1 | G30: 1 | H30: N/A — STARTING not recorded (CONFIRMED / STARTING) | I30: 0.092% (CONFIRMED / 2166 scanned) | J30: RECORDED — recorded engine run (REAL_1YEAR_BACKTEST_RESULT.json)
A31: 2025-10-14 | B31: 2188 | C31: N/A (not stored) | D31: 3 | E31: 3 | F31: 1 | G31: 2 | H31: N/A — STARTING not recorded (CONFIRMED / STARTING) | I31: 0.137% (CONFIRMED / 2188 scanned) | J31: RECORDED — recorded engine run (REAL_1YEAR_BACKTEST_RESULT.json)
A32: 2025-10-15 | B32: 2184 | C32: N/A (not stored) | D32: 9 | E32: 9 | F32: 4 | G32: 5 | H32: N/A — STARTING not recorded (CONFIRMED / STARTING) | I32: 0.412% (CONFIRMED / 2184 scanned) | J32: RECORDED — recorded engine run (REAL_1YEAR_BACKTEST_RESULT.json)
A33: 2025-10-16 | B33: 2181 | C33: N/A (not stored) | D33: 6 | E33: 6 | F33: 2 | G33: 4 | H33: N/A — STARTING not recorded (CONFIRMED / STARTING) | I33: 0.275% (CONFIRMED / 2181 scanned) | J33: RECORDED — recorded engine run (REAL_1YEAR_BACKTEST_RESULT.json)
... A250: 2026-09-03 | B250: 2469 | C250: N/A (not stored) | D250: 5 | E250: 5 | F250: 4 | G250: 1 | H250: N/A — STARTING not recorded (CONFIRMED / STARTING) | I250: 0.203% (CONFIRMED / 2469 scanned) | J250: RECORDED — recorded engine run (REAL_1YEAR_BACKTEST_RESULT.json)
A251: 2026-09-04 | B251: MISSING / UNVERIFIED | C251: MISSING / UNVERIFIED | D251: MISSING / UNVERIFIED | E251: MISSING / UNVERIFIED | F251: MISSING / UNVERIFIED | G251: MISSING / UNVERIFIED | H251: MISSING / UNVERIFIED | I251: MISSING / UNVERIFIED | J251: MISSING / UNVERIFIED — recorded run saw zero-filled delivery data on this date; zero events there is NOT a verified zero
A252: 2026-09-07 | B252: MISSING / UNVERIFIED | C252: MISSING / UNVERIFIED | D252: MISSING / UNVERIFIED | E252: MISSING / UNVERIFIED | F252: MISSING / UNVERIFIED | G252: MISSING / UNVERIFIED | H252: MISSING / UNVERIFIED | I252: MISSING / UNVERIFIED | J252: MISSING / UNVERIFIED — recorded run saw zero-filled delivery data on this date; zero events there is NOT a verified zero
A253: 2026-09-08 | B253: MISSING / UNVERIFIED | C253: MISSING / UNVERIFIED | D253: MISSING / UNVERIFIED | E253: MISSING / UNVERIFIED | F253: MISSING / UNVERIFIED | G253: MISSING / UNVERIFIED | H253: MISSING / UNVERIFIED | I253: MISSING / UNVERIFIED | J253: MISSING / UNVERIFIED — recorded run saw zero-filled delivery data on this date; zero events there is NOT a verified zero
A254: 2026-09-09 | B254: MISSING / UNVERIFIED | C254: MISSING / UNVERIFIED | D254: MISSING / UNVERIFIED | E254: MISSING / UNVERIFIED | F254: MISSING / UNVERIFIED | G254: MISSING / UNVERIFIED | H254: MISSING / UNVERIFIED | I254: MISSING / UNVERIFIED | J254: MISSING / UNVERIFIED — recorded run saw zero-filled delivery data on this date; zero events there is NOT a verified zero
A255: 2026-09-10 | B255: MISSING / UNVERIFIED | C255: MISSING / UNVERIFIED | D255: MISSING / UNVERIFIED | E255: MISSING / UNVERIFIED | F255: MISSING / UNVERIFIED | G255: MISSING / UNVERIFIED | H255: MISSING / UNVERIFIED | I255: MISSING / UNVERIFIED | J255: MISSING / UNVERIFIED — recorded run saw zero-filled delivery data on this date; zero events there is NOT a verified zero
A256: 2026-09-11 | B256: MISSING / UNVERIFIED | C256: MISSING / UNVERIFIED | D256: MISSING / UNVERIFIED | E256: MISSING / UNVERIFIED | F256: MISSING / UNVERIFIED | G256: MISSING / UNVERIFIED | H256: MISSING / UNVERIFIED | I256: MISSING / UNVERIFIED | J256: MISSING / UNVERIFIED — recorded run saw zero-filled delivery data on this date; zero events there is NOT a verified zero
A257: 2026-09-15 | B257: MISSING / UNVERIFIED | C257: MISSING / UNVERIFIED | D257: MISSING / UNVERIFIED | E257: MISSING / UNVERIFIED | F257: MISSING / UNVERIFIED | G257: MISSING / UNVERIFIED | H257: MISSING / UNVERIFIED | I257: MISSING / UNVERIFIED | J257: MISSING / UNVERIFIED — recorded run saw zero-filled delivery data on this date; zero events there is NOT a verified zero
A258: 2026-09-16 | B258: MISSING / UNVERIFIED | C258: MISSING / UNVERIFIED | D258: MISSING / UNVERIFIED | E258: MISSING / UNVERIFIED | F258: MISSING / UNVERIFIED | G258: MISSING / UNVERIFIED | H258: MISSING / UNVERIFIED | I258: MISSING / UNVERIFIED | J258: MISSING / UNVERIFIED — no recorded V15 run covers this date (raw files exist, no verdicts stored)
A259: 2026-09-17 | B259: MISSING / UNVERIFIED | C259: MISSING / UNVERIFIED | D259: MISSING / UNVERIFIED | E259: MISSING / UNVERIFIED | F259: MISSING / UNVERIFIED | G259: MISSING / UNVERIFIED | H259: MISSING / UNVERIFIED | I259: MISSING / UNVERIFIED | J259: MISSING / UNVERIFIED — no recorded V15 run covers this date (raw files exist, no verdicts stored)
A260: 2026-09-18 | B260: MISSING / UNVERIFIED | C260: MISSING / UNVERIFIED | D260: MISSING / UNVERIFIED | E260: MISSING / UNVERIFIED | F260: MISSING / UNVERIFIED | G260: MISSING / UNVERIFIED | H260: MISSING / UNVERIFIED | I260: MISSING / UNVERIFIED | J260: MISSING / UNVERIFIED — no recorded V15 run covers this date (raw files exist, no verdicts stored)
A261: 2026-09-21 | B261: MISSING / UNVERIFIED | C261: MISSING / UNVERIFIED | D261: MISSING / UNVERIFIED | E261: MISSING / UNVERIFIED | F261: MISSING / UNVERIFIED | G261: MISSING / UNVERIFIED | H261: MISSING / UNVERIFIED | I261: MISSING / UNVERIFIED | J261: MISSING / UNVERIFIED — no recorded V15 run covers this date (raw files exist, no verdicts stored)
A262: 2026-09-22 | B262: MISSING / UNVERIFIED | C262: MISSING / UNVERIFIED | D262: MISSING / UNVERIFIED | E262: MISSING / UNVERIFIED | F262: MISSING / UNVERIFIED | G262: MISSING / UNVERIFIED | H262: MISSING / UNVERIFIED | I262: MISSING / UNVERIFIED | J262: MISSING / UNVERIFIED — no recorded V15 run covers this date (raw files exist, no verdicts stored)
... A264: 2026-09-24 | B264: MISSING / UNVERIFIED | C264: MISSING / UNVERIFIED | D264: MISSING / UNVERIFIED | E264: MISSING / UNVERIFIED | F264: MISSING / UNVERIFIED | G264: MISSING / UNVERIFIED | H264: MISSING / UNVERIFIED | I264: MISSING / UNVERIFIED | J264: MISSING / UNVERIFIED — no recorded V15 run covers this date (raw files exist, no verdicts stored)

Sheet T5_Weekly
A1: Week (ISO) | B1: Session range | C1: Trading Sessions | D1: Verified Sessions | E1: Missing Sessions | F1: Total STARTING | G1: Total CONFIRMED (verified sessions only) | H1: Unique Confirmed Stocks | I1: Repeat Confirmations | J1: Average Confirmed per Verified Session | K1: Confirmation Rate (CONFIRMED / STARTING) | L1: Supplementary rate | M1: Risen (current) | N1: Fallen (current) | O1: Unchanged | P1: No Current Data | Q1: Up vs Down outcome
A2: 2025-W36 | B2: 2025-09-02 → 2025-09-05 | C2: 4 | D2: 0 | E2: 4 | F2: N/A (not stored) | G2: MISSING / UNVERIFIED | H2: MISSING / UNVERIFIED | I2: MISSING / UNVERIFIED | J2: MISSING / UNVERIFIED | K2: N/A — STARTING not recorded | L2: MISSING / UNVERIFIED | M2: 0 | N2: 0 | O2: 0 | P2: 0 | Q2: MISSING / UNVERIFIED
A3: 2025-W37 | B3: 2025-09-08 → 2025-09-12 | C3: 5 | D3: 0 | E3: 5 | F3: N/A (not stored) | G3: MISSING / UNVERIFIED | H3: MISSING / UNVERIFIED | I3: MISSING / UNVERIFIED | J3: MISSING / UNVERIFIED | K3: N/A — STARTING not recorded | L3: MISSING / UNVERIFIED | M3: 0 | N3: 0 | O3: 0 | P3: 0 | Q3: MISSING / UNVERIFIED
A4: 2025-W38 | B4: 2025-09-15 → 2025-09-19 | C4: 5 | D4: 0 | E4: 5 | F4: N/A (not stored) | G4: MISSING / UNVERIFIED | H4: MISSING / UNVERIFIED | I4: MISSING / UNVERIFIED | J4: MISSING / UNVERIFIED | K4: N/A — STARTING not recorded | L4: MISSING / UNVERIFIED | M4: 0 | N4: 0 | O4: 0 | P4: 0 | Q4: MISSING / UNVERIFIED
A5: 2025-W39 | B5: 2025-09-22 → 2025-09-26 | C5: 5 | D5: 0 | E5: 5 | F5: N/A (not stored) | G5: MISSING / UNVERIFIED | H5: MISSING / UNVERIFIED | I5: MISSING / UNVERIFIED | J5: MISSING / UNVERIFIED | K5: N/A — STARTING not recorded | L5: MISSING / UNVERIFIED | M5: 0 | N5: 0 | O5: 0 | P5: 0 | Q5: MISSING / UNVERIFIED
A6: 2025-W40 | B6: 2025-09-29 → 2025-10-03 | C6: 4 | D6: 3 | E6: 1 | F6: N/A (not stored) | G6: 22 | H6: 20 | I6: 2 | J6: 7.33 (÷ 3 verified sessions) | K6: N/A — STARTING not recorded | L6: 3.52 per 1,000 scanned (6,258 stock-sessions) | M6: 8 | N6: 14 | O6: 0 | P6: 0 | Q6: 8 up / 14 down
A7: 2025-W41 | B7: 2025-10-06 → 2025-10-10 | C7: 5 | D7: 5 | E7: 0 | F7: N/A (not stored) | G7: 24 | H7: 21 | I7: 6 | J7: 4.80 (÷ 5 verified sessions) | K7: N/A — STARTING not recorded | L7: 2.24 per 1,000 scanned (10,693 stock-sessions) | M7: 8 | N7: 15 | O7: 0 | P7: 1 | Q7: 8 up / 15 down
A8: 2025-W42 | B8: 2025-10-13 → 2025-10-17 | C8: 5 | D8: 5 | E8: 0 | F8: N/A (not stored) | G8: 24 | H8: 22 | I8: 10 | J8: 4.80 (÷ 5 verified sessions) | K8: N/A — STARTING not recorded | L8: 2.20 per 1,000 scanned (10,903 stock-sessions) | M8: 8 | N8: 16 | O8: 0 | P8: 0 | Q8: 8 up / 16 down
A9: 2025-W43 | B9: 2025-10-20 → 2025-10-24 | C9: 4 | D9: 4 | E9: 0 | F9: N/A (not stored) | G9: 1 | H9: 1 | I9: 1 | J9: 0.25 (÷ 4 verified sessions) | K9: N/A — STARTING not recorded | L9: 0.11 per 1,000 scanned (8,787 stock-sessions) | M9: 0 | N9: 1 | O9: 0 | P9: 0 | Q9: 0 up / 1 down
A10: 2025-W44 | B10: 2025-10-27 → 2025-10-31 | C10: 5 | D10: 5 | E10: 0 | F10: N/A (not stored) | G10: 20 | H10: 18 | I10: 5 | J10: 4.00 (÷ 5 verified sessions) | K10: N/A — STARTING not recorded | L10: 1.82 per 1,000 scanned (10,996 stock-sessions) | M10: 9 | N10: 11 | O10: 0 | P10: 0 | Q10: 9 up / 11 down
A11: 2025-W45 | B11: 2025-11-03 → 2025-11-07 | C11: 4 | D11: 4 | E11: 0 | F11: N/A (not stored) | G11: 16 | H11: 13 | I11: 10 | J11: 4.00 (÷ 4 verified sessions) | K11: N/A — STARTING not recorded | L11: 1.81 per 1,000 scanned (8,863 stock-sessions) | M11: 6 | N11: 10 | O11: 0 | P11: 0 | Q11: 6 up / 10 down
A12: 2025-W46 | B12: 2025-11-10 → 2025-11-14 | C12: 5 | D12: 5 | E12: 0 | F12: N/A (not stored) | G12: 21 | H12: 17 | I12: 11 | J12: 4.20 (÷ 5 verified sessions) | K12: N/A — STARTING not recorded | L12: 1.88 per 1,000 scanned (11,159 stock-sessions) | M12: 12 | N12: 8 | O12: 0 | P12: 1 | Q12: 12 up / 8 down
A13: 2025-W47 | B13: 2025-11-17 → 2025-11-21 | C13: 5 | D13: 5 | E13: 0 | F13: N/A (not stored) | G13: 3 | H13: 3 | I13: 2 | J13: 0.60 (÷ 5 verified sessions) | K13: N/A — STARTING not recorded | L13: 0.27 per 1,000 scanned (11,291 stock-sessions) | M13: 1 | N13: 2 | O13: 0 | P13: 0 | Q13: 1 up / 2 down
A14: 2025-W48 | B14: 2025-11-24 → 2025-11-28 | C14: 5 | D14: 5 | E14: 0 | F14: N/A (not stored) | G14: 9 | H14: 9 | I14: 4 | J14: 1.80 (÷ 5 verified sessions) | K14: N/A — STARTING not recorded | L14: 0.79 per 1,000 scanned (11,343 stock-sessions) | M14: 6 | N14: 3 | O14: 0 | P14: 0 | Q14: 6 up / 3 down
A15: 2025-W49 | B15: 2025-12-01 → 2025-12-05 | C15: 5 | D15: 5 | E15: 0 | F15: N/A (not stored) | G15: 6 | H15: 6 | I15: 4 | J15: 1.20 (÷ 5 verified sessions) | K15: N/A — STARTING not recorded | L15: 0.53 per 1,000 scanned (11,380 stock-sessions) | M15: 4 | N15: 2 | O15: 0 | P15: 0 | Q15: 4 up / 2 down
A16: 2025-W50 | B16: 2025-12-08 → 2025-12-12 | C16: 5 | D16: 5 | E16: 0 | F16: N/A (not stored) | G16: 19 | H16: 19 | I16: 16 | J16: 3.80 (÷ 5 verified sessions) | K16: N/A — STARTING not recorded | L16: 1.66 per 1,000 scanned (11,428 stock-sessions) | M16: 9 | N16: 10 | O16: 0 | P16: 0 | Q16: 9 up / 10 down
A17: 2025-W51 | B17: 2025-12-15 → 2025-12-19 | C17: 5 | D17: 5 | E17: 0 | F17: N/A (not stored) | G17: 14 | H17: 14 | I17: 14 | J17: 2.80 (÷ 5 verified sessions) | K17: N/A — STARTING not recorded | L17: 1.22 per 1,000 scanned (11,468 stock-sessions) | M17: 7 | N17: 6 | O17: 0 | P17: 1 | Q17: 7 up / 6 down
... A54: 2026-W36 | B54: 2026-08-31 → 2026-09-04 | C54: 5 | D54: 4 | E54: 1 | F54: N/A (not stored) | G54: 21 | H54: 19 | I54: 19 | J54: 5.25 (÷ 4 verified sessions) | K54: N/A — STARTING not recorded | L54: 2.12 per 1,000 scanned (9,884 stock-sessions) | M54: 0 | N54: 21 | O54: 0 | P54: 0 | Q54: 0 up / 21 down
A55: 2026-W37 | B55: 2026-09-07 → 2026-09-11 | C55: 5 | D55: 0 | E55: 5 | F55: N/A (not stored) | G55: MISSING / UNVERIFIED | H55: MISSING / UNVERIFIED | I55: MISSING / UNVERIFIED | J55: MISSING / UNVERIFIED | K55: N/A — STARTING not recorded | L55: MISSING / UNVERIFIED | M55: 0 | N55: 0 | O55: 0 | P55: 0 | Q55: MISSING / UNVERIFIED
A56: 2026-W38 | B56: 2026-09-15 → 2026-09-18 | C56: 4 | D56: 0 | E56: 4 | F56: N/A (not stored) | G56: MISSING / UNVERIFIED | H56: MISSING / UNVERIFIED | I56: MISSING / UNVERIFIED | J56: MISSING / UNVERIFIED | K56: N/A — STARTING not recorded | L56: MISSING / UNVERIFIED | M56: 0 | N56: 0 | O56: 0 | P56: 0 | Q56: MISSING / UNVERIFIED
A57: 2026-W39 | B57: 2026-09-21 → 2026-09-24 | C57: 4 | D57: 0 | E57: 4 | F57: N/A (not stored) | G57: MISSING / UNVERIFIED | H57: MISSING / UNVERIFIED | I57: MISSING / UNVERIFIED | J57: MISSING / UNVERIFIED | K57: N/A — STARTING not recorded | L57: MISSING / UNVERIFIED | M57: 0 | N57: 0 | O57: 0 | P57: 0 | Q57: MISSING / UNVERIFIED

Sheet T6_Monthly
A1: Month | B1: Session range | C1: Trading Sessions | D1: Verified Sessions | E1: Missing Sessions | F1: Total STARTING | G1: Total CONFIRMED (verified sessions only) | H1: Unique Confirmed Stocks | I1: Repeat Confirmations | J1: Average Confirmed per Verified Session | K1: Confirmation Rate (CONFIRMED / STARTING) | L1: Supplementary rate | M1: Currently Risen | N1: Currently Fallen | O1: Currently Unchanged | P1: No Current Data
A2: 2025-09 | B2: 2025-09-02 → 2025-09-30 | C2: 21 | D2: 1 | E2: 20 | F2: N/A (not stored) | G2: 0 | H2: 0 | I2: 0 | J2: 0.00 (÷ 1 verified sessions) | K2: N/A — STARTING not recorded | L2: 0.00 per 1,000 scanned (2,085 stock-sessions) | M2: 0 | N2: 0 | O2: 0 | P2: 0
A3: 2025-10 | B3: 2025-10-01 → 2025-10-31 | C3: 21 | D3: 21 | E3: 0 | F3: N/A (not stored) | G3: 91 | H3: 67 | I3: 24 | J3: 4.33 (÷ 21 verified sessions) | K3: N/A — STARTING not recorded | L3: 2.00 per 1,000 scanned (45,552 stock-sessions) | M3: 33 | N3: 57 | O3: 0 | P3: 1
A4: 2025-11 | B4: 2025-11-03 → 2025-11-28 | C4: 19 | D4: 19 | E4: 0 | F4: N/A (not stored) | G4: 49 | H4: 39 | I4: 27 | J4: 2.58 (÷ 19 verified sessions) | K4: N/A — STARTING not recorded | L4: 1.15 per 1,000 scanned (42,656 stock-sessions) | M4: 25 | N4: 23 | O4: 0 | P4: 1
A5: 2025-12 | B5: 2025-12-01 → 2025-12-31 | C5: 22 | D5: 22 | E5: 0 | F5: N/A (not stored) | G5: 50 | H5: 41 | I5: 37 | J5: 2.27 (÷ 22 verified sessions) | K5: N/A — STARTING not recorded | L5: 0.99 per 1,000 scanned (50,380 stock-sessions) | M5: 22 | N5: 27 | O5: 0 | P5: 1
A6: 2026-01 | B6: 2026-01-01 → 2026-01-30 | C6: 20 | D6: 20 | E6: 0 | F6: N/A (not stored) | G6: 109 | H6: 75 | I6: 73 | J6: 5.45 (÷ 20 verified sessions) | K6: N/A — STARTING not recorded | L6: 2.31 per 1,000 scanned (47,117 stock-sessions) | M6: 29 | N6: 79 | O6: 0 | P6: 1
A7: 2026-02 | B7: 2026-02-02 → 2026-02-27 | C7: 20 | D7: 20 | E7: 0 | F7: N/A (not stored) | G7: 84 | H7: 61 | I7: 74 | J7: 4.20 (÷ 20 verified sessions) | K7: N/A — STARTING not recorded | L7: 1.75 per 1,000 scanned (47,878 stock-sessions) | M7: 22 | N7: 62 | O7: 0 | P7: 0
A8: 2026-03 | B8: 2026-03-02 → 2026-03-30 | C8: 19 | D8: 19 | E8: 0 | F8: N/A (not stored) | G8: 40 | H8: 32 | I8: 34 | J8: 2.11 (÷ 19 verified sessions) | K8: N/A — STARTING not recorded | L8: 0.88 per 1,000 scanned (45,700 stock-sessions) | M8: 16 | N8: 24 | O8: 0 | P8: 0
A9: 2026-04 | B9: 2026-04-01 → 2026-04-30 | C9: 20 | D9: 20 | E9: 0 | F9: N/A (not stored) | G9: 117 | H9: 78 | I9: 102 | J9: 5.85 (÷ 20 verified sessions) | K9: N/A — STARTING not recorded | L9: 2.44 per 1,000 scanned (47,901 stock-sessions) | M9: 65 | N9: 52 | O9: 0 | P9: 0
A10: 2026-05 | B10: 2026-05-04 → 2026-05-29 | C10: 19 | D10: 19 | E10: 0 | F10: N/A (not stored) | G10: 70 | H10: 53 | I10: 62 | J10: 3.68 (÷ 19 verified sessions) | K10: N/A — STARTING not recorded | L10: 1.55 per 1,000 scanned (45,268 stock-sessions) | M10: 22 | N10: 48 | O10: 0 | P10: 0
